Traceback (most recent call last):
  File "C:\Users\paulj\AppData\Local\Packages\PythonSoftwareFoundation.Python.3.10_qbz5n2kfra8p0\LocalCache\local-packages\Python310\site-packages\jupyter_cache\executors\utils.py", line 51, in single_nb_execution
    executenb(
  File "C:\Users\paulj\AppData\Local\Packages\PythonSoftwareFoundation.Python.3.10_qbz5n2kfra8p0\LocalCache\local-packages\Python310\site-packages\nbclient\client.py", line 1085, in execute
    return NotebookClient(nb=nb, resources=resources, km=km, **kwargs).execute()
  File "C:\Users\paulj\AppData\Local\Packages\PythonSoftwareFoundation.Python.3.10_qbz5n2kfra8p0\LocalCache\local-packages\Python310\site-packages\nbclient\util.py", line 84, in wrapped
    return just_run(coro(*args, **kwargs))
  File "C:\Users\paulj\AppData\Local\Packages\PythonSoftwareFoundation.Python.3.10_qbz5n2kfra8p0\LocalCache\local-packages\Python310\site-packages\nbclient\util.py", line 62, in just_run
    return loop.run_until_complete(coro)
  File "C:\Program Files\WindowsApps\PythonSoftwareFoundation.Python.3.10_3.10.752.0_x64__qbz5n2kfra8p0\lib\asyncio\base_events.py", line 641, in run_until_complete
    return future.result()
  File "C:\Users\paulj\AppData\Local\Packages\PythonSoftwareFoundation.Python.3.10_qbz5n2kfra8p0\LocalCache\local-packages\Python310\site-packages\nbclient\client.py", line 551, in async_execute
    await self.async_execute_cell(
  File "C:\Users\paulj\AppData\Local\Packages\PythonSoftwareFoundation.Python.3.10_qbz5n2kfra8p0\LocalCache\local-packages\Python310\site-packages\nbclient\client.py", line 846, in async_execute_cell
    self._check_raise_for_error(cell, exec_reply)
  File "C:\Users\paulj\AppData\Local\Packages\PythonSoftwareFoundation.Python.3.10_qbz5n2kfra8p0\LocalCache\local-packages\Python310\site-packages\nbclient\client.py", line 748, in _check_raise_for_error
    raise CellExecutionError.from_cell_and_msg(cell, exec_reply_content)
nbclient.exceptions.CellExecutionError: An error occurred while executing the following cell:
------------------
from IPython.display import Video
Video("videos/CyberChef.mp4")
------------------

[1;31m---------------------------------------------------------------------------[0m
[1;31mValueError[0m                                Traceback (most recent call last)
[1;32m~\AppData\Local\Temp\ipykernel_2444\1748887761.py[0m in [0;36m<module>[1;34m[0m
[0;32m      1[0m [1;32mfrom[0m [0mIPython[0m[1;33m.[0m[0mdisplay[0m [1;32mimport[0m [0mVideo[0m[1;33m[0m[1;33m[0m[0m
[1;32m----> 2[1;33m [0mVideo[0m[1;33m([0m[1;34m"videos/CyberChef.mp4"[0m[1;33m)[0m[1;33m[0m[1;33m[0m[0m
[0m
[1;32m~\AppData\Local\Packages\PythonSoftwareFoundation.Python.3.10_qbz5n2kfra8p0\LocalCache\local-packages\Python310\site-packages\IPython\core\display.py[0m in [0;36m__init__[1;34m(self, data, url, filename, embed, mimetype, width, height, html_attributes)[0m
[0;32m   1408[0m                 [1;34m"Consider passing Video(url='...')"[0m[1;33m,[0m[1;33m[0m[1;33m[0m[0m
[0;32m   1409[0m             ])
[1;32m-> 1410[1;33m             [1;32mraise[0m [0mValueError[0m[1;33m([0m[0mmsg[0m[1;33m)[0m[1;33m[0m[1;33m[0m[0m
[0m[0;32m   1411[0m [1;33m[0m[0m
[0;32m   1412[0m         [0mself[0m[1;33m.[0m[0mmimetype[0m [1;33m=[0m [0mmimetype[0m[1;33m[0m[1;33m[0m[0m

[1;31mValueError[0m: To embed videos, you must pass embed=True (this may make your notebook files huge)
Consider passing Video(url='...')
ValueError: To embed videos, you must pass embed=True (this may make your notebook files huge)
Consider passing Video(url='...')

